Traceback (most recent call last):
  File "/Users/dorme/.pyenv/versions/3.7.7/lib/python3.7/site-packages/jupyter_cache/executors/utils.py", line 56, in single_nb_execution
    record_timing=False,
  File "/Users/dorme/.pyenv/versions/3.7.7/lib/python3.7/site-packages/nbclient/client.py", line 1087, in execute
    return NotebookClient(nb=nb, resources=resources, km=km, **kwargs).execute()
  File "/Users/dorme/.pyenv/versions/3.7.7/lib/python3.7/site-packages/nbclient/util.py", line 74, in wrapped
    return just_run(coro(*args, **kwargs))
  File "/Users/dorme/.pyenv/versions/3.7.7/lib/python3.7/site-packages/nbclient/util.py", line 53, in just_run
    return loop.run_until_complete(coro)
  File "/Users/dorme/.pyenv/versions/3.7.7/lib/python3.7/asyncio/base_events.py", line 587, in run_until_complete
    return future.result()
  File "/Users/dorme/.pyenv/versions/3.7.7/lib/python3.7/site-packages/nbclient/client.py", line 541, in async_execute
    cell, index, execution_count=self.code_cells_executed + 1
  File "/Users/dorme/.pyenv/versions/3.7.7/lib/python3.7/site-packages/nbclient/client.py", line 832, in async_execute_cell
    self._check_raise_for_error(cell, exec_reply)
  File "/Users/dorme/.pyenv/versions/3.7.7/lib/python3.7/site-packages/nbclient/client.py", line 740, in _check_raise_for_error
    raise CellExecutionError.from_cell_and_msg(cell, exec_reply['content'])
nbclient.exceptions.CellExecutionError: An error occurred while executing the following cell:
------------------
# Load a vector shapefile
ne_110 <- st_read('data/ne_110m_admin_0_countries/ne_110m_admin_0_countries.shp')
# Also load some WHO data on 2016 life expectancy
# see: http://apps.who.int/gho/athena/api/GHO/WHOSIS_000001?filter=YEAR:2016;SEX:BTSX&format=csv
life_exp <- read.csv(file = "data/WHOSIS_000001.csv")
------------------

Error: Cannot open "data/ne_110m_admin_0_countries/ne_110m_admin_0_countries.shp"; The file doesn't seem to exist.
Traceback:

1. st_read("data/ne_110m_admin_0_countries/ne_110m_admin_0_countries.shp")
2. st_read.character("data/ne_110m_admin_0_countries/ne_110m_admin_0_countries.shp")
3. CPL_read_ogr(dsn, layer, query, as.character(options), quiet, 
 .     type, fid_column_name, drivers, wkt_filter, promote_to_multi, 
 .     int64_as_string, dsn_exists, dsn_isdb, getOption("width"))
ERROR: Error: Cannot open "data/ne_110m_admin_0_countries/ne_110m_admin_0_countries.shp"; The file doesn't seem to exist.


